Workbook

Sheet Homologación Estados
A1: Llave | B1: Estados Consolidados
A2: No Vigente00 | B2: No Vigente
A3: No Vigente0Ing No RecibidaAs Built No Recibido00 | B3: No Vigente
A4: No VigenteAs Built No Recibido00 | B4: No Vigente
A5: No VigenteIng No Recibida00 | B5: No Vigente
A6: No VigenteIng No RecibidaAs Built No Recibido00 | B6: No Vigente
A7: No VigenteTSS Aprobado con observacionesIng No RecibidaAs Built No Recibido00 | B7: No Vigente
A8: No VigenteTSS AprobadoIng Aprobada con ObservacionesAs Built Detenido00 | B8: No Vigente
A9: No VigenteTSS AprobadoIng Aprobada con ObservacionesAs Built No Recibido00 | B9: No Vigente
A10: No VigenteTSS AprobadoIng AprobadaAs Built Detenido00 | B10: No Vigente
A11: No VigenteTSS AprobadoIng AprobadaAs Built En Revisión00 | B11: No Vigente
A12: No VigenteTSS AprobadoIng AprobadaAs Built No Recibido00 | B12: No Vigente
... A90: VigenteTSS RechazadoIng No RecibidaAs Built No Recibido00 | B90: En Etapa de TSS 4G

Sheet Tracker
B2: =SUBTOTAL(3,B4:B1448) -> 1
A3: Busqueda | B3: ID Sitio | C3: Nombre Sitio | D3: N Region | E3: LAT | F3: LONG | G3: Region | H3: Comuna | I3: Dirección | J3: Proyecto | K3: Vigencia | L3: Concurso 5G | M3: Forecast Inmobiliaria | N3: Etapa Subtel | O3: Operador | P3: Colo/BTS | Q3: Comentario | R3: Tipo Estructura | S3: RF ALTURA (m) | T3: ID OOII | U3: Asignación TSS | V3: W Asignación TSS | W3: Presentación TSS | X3: Presentación Correcciones TSS Observado | Y3: W Presentación TSS | Z3: Fecha de Solicitud de Revisión PMO | AA3: Fecha Máxima Respuesta | AB3: SLA Revisión_1 | AC3: Status TSS RF | AD3: Comentarios TSS RF | AE3: TSS Fecha de Aprobación/obs RF | AF3: W TSS Aprobación RF | AG3: Status TSS OOCC | AH3: Comentarios TSS OOCC | AI3: TSS Fecha de Aprobación/Obs OOCC | AJ3: W TSS Aprobación OOCC | AK3: Status TSS Implementación | AL3: Comentarios TSS Implementación | AM3: TSS Fecha de Aprobación/obs Implementación | AN3: W TSS Aprobación Implementación | AO3: Status TSS ECE | AP3: Comentarios TSS ECE | AQ3: TSS Fecha de Aprobación/Obs ECE | AR3: W TSS Aprobación ECE | AS3: Status TSS MMOO | AT3: Comentarios TSS MMOO | AU3: TSS Fecha de Aprobación/Obs MMOO | AV3: W TSS Aprobación MMOO | AW3: Fecha TSS Aprobación/Obs | AX3: W TSS Aprobación | AY3: Status TSS | AZ3: Status FC | BA3: Status Contrato | BB3: Presentación Ingeniería OOII | BC3: Presentación Correcciones Ing OOII | BD3: Fecha de envio Ing de PMO a Áreas | BE3: Week de Envio Ing | BF3: Fecha Maxima Respuesta Ing | BG3: Week Respuesta Ing | BH3: SLA Revisión2 | BI3: Status Ing OOCC | BJ3: Comentarios Ing OOCC | BK3: Ing Fecha de Aprobación/Obs OOCC | BL3: W Ing Aprobación OOCC | BM3: Status Ing RF | BN3: Comentarios Ing RF | BO3: Ing Fecha de Aprobación/Obs RF | BP3: W Ing Aprobación RF | BQ3: Status Ing Implementación | BR3: Comentarios Ing Implementación | BS3: Ing Fecha de Aprobación/Obs Implementación | BT3: W Ing Aprobación Implementación | BU3: Status Ing ECE | BV3: Comentarios Ing ECE | BW3: Ing Fecha de Aprobación/Obs ECE | BX3: W Ing Aprobación ECE | BY3: Fecha Ing Aprobación/Obs | BZ3: W Ing Aprobación | CA3: Status Ing | CB3: Estado OOCC | CC3: Estado OOEE | CD3: Disponibilidad Energía Provisoria | CE3: Disponibilidad Empalme | CF3: Presentación As built OOII | CG3: Presentación Correcciones As built OOII | CH3: Fecha de envio Asbuilt de PMO a Áreas | CI3: Week de Envio As built | CJ3: Fecha Respuesta As built | CK3: Week Respuesta As built | CL3: SLA Revisión3 | CM3: Status Asbuilt OOCC | CN3: Comentarios As built OOCC | CO3: As Built Fecha de Aprobación/Obs OOCC | CP3: W Asbuilt Aprobación OOCC | CQ3: Status As Built RF | CR3: Comentarios As built RF | CS3: As built Fecha de Aprobación/Obs RF | CT3: W Asbuilt Aprobación RF | CU3: Status As Built Implementación | CV3: Comentarios As built Implementación | CW3: Fecha de Aprobación/Obs Implementación | CX3: W Asbuilt Aprobación Implementación | CY3: Status As built ECE | CZ3: Comentarios Asbuilt ECE | DA3: As Built Fecha de Aprobación/Obs ECE | DB3: W Asbuilt Aprobación ECE | DC3: Fecha Asbuilt Aprobación/Obs | DD3: W Asbuilt Aprobación/Obs | DE3: Status Asbuilt | DF3: API Firmada | DG3: Responsable Gabinete | DH3: Rectificador Instalado | DI3: Fecha de Inicio Gestión DOM | DJ3: Status DOM | DK3: Tipo Tx | DL3: Status Tx | DM3: Forecast Entrega Tx | DN3: Fecha Real de Entrega | DO3: Fecha Entrega Certficado | DP3: Observación | DQ3: Proveedor UAN | DR3: Forecast Instalación UAN | DS3: Fecha Real Inst. UAN | DT3: Status IPRAN | DU3: Fecha de Envio a Equipo Implementador RF | DV3: Fecha Sitio On Air | DW3: Sitios On air | DX3: Fecha de recepción de llaves | DY3: Recibida por | DZ3: Observación4 | EA3: OC Inmobiliaria | EB3: Status Sitio | EC3: Plan 2024 | ED3: Plan 2025 (90) | EE3: Plan 290 | EF3: Forecast OOII | EG3: Frorecast OOII W | EH3: Riesgo | EI3: Comentario Riesgo | EJ3: Llave
A4: =IFERROR(IF(VLOOKUP(B4,SEARCH!A:A,1,0)=B4,"OK",""),"") | B4: 06_732 | C4: Graneros Luis Cruz Martinez | D4: 6 | E4: -34.06658 | F4: -70.72095 | G4: Libertador General Bernardo O'Higgins | H4: Graneros | I4: Nemesio Antunes, vereda frente a la casa N° 0306 | J4: Fase 1 - On Hold RF | K4: No Vigente | L4: No aplica | M4: 3 | O4: 0 | P4: BTS | Q4: 5-2-2025 Se informa por RF que sitios salen de plan 2024 (Correo Delfos) | R4: POSTE METALICO | S4: 18 | U4: 0 | V4: =IF(U4="","",IF(U4="TBD","TBD",IF(U4="N/A","N/A","W"&TEXT(WEEKNUM(U4,21),"00")&" "&YEAR(U4)))) -> W52 1900 | Y4: =IF(X4="","",IF(X4="TBD","TBD",IF(X4="N/A","N/A","W"&TEXT(WEEKNUM(X4,21),"00")&" "&YEAR(X4)))) | AB4: =+IF(Z4="",0,AA4-Z4) -> 0 | AC4: TSS No Recibido | AF4: =IF(AE4="","",IF(AE4="TBD","TBD",IF(AE4="N/A","N/A","W"&TEXT(WEEKNUM(AE4,21),"00")&" "&YEAR(AE4)))) | AG4: TSS No Recibido | AJ4: =IF(AI4="","",IF(AI4="TBD","TBD",IF(AI4="N/A","N/A","W"&TEXT(WEEKNUM(AI4,21),"00")&" "&YEAR(AI4)))) | AK4: TSS No Recibido | AN4: =IF(AM4="","",IF(AM4="TBD","TBD",IF(AM4="N/A","N/A","W"&TEXT(WEEKNUM(AM4,21),"00")&" "&YEAR(AM4)))) | AO4: TSS No Recibido | AR4: =IF(AQ4="","",IF(AQ4="TBD","TBD",IF(AQ4="N/A","N/A","W"&TEXT(WEEKNUM(AQ4,21),"00")&" "&YEAR(AQ4)))) | AX4: =IF(AW4="","",IF(AW4="TBD","TBD",IF(AW4="N/A","N/A","W"&TEXT(WEEKNUM(AW4,21),"00")&" "&YEAR(AW4)))) | AY4: TSS No Recibido 4G | AZ4: Pendiente FC | BA4: Contrato No Firmado | BE4: =IF(BD4="","",IF(BD4="TBD","TBD",IF(BD4="N/A","N/A","W"&TEXT(WEEKNUM(BD4,21),"00")&" "&YEAR(BD4)))) | BG4: =IF(BF4="","",IF(BF4="TBD","TBD",IF(BF4="N/A","N/A","W"&TEXT(WEEKNUM(BF4,21),"00")&" "&YEAR(BF4)))) | BH4: =+IF(BF4="",0,(BF4-BD4)) -> 0 | BI4: Ing No Recibida | BL4: =IF(BK4="","",IF(BK4="TBD","TBD",IF(BK4="N/A","N/A","W"&TEXT(WEEKNUM(BK4,21),"00")&" "&YEAR(BK4)))) | BM4: Ing No Recibida | BP4: =IF(BO4="","",IF(BO4="TBD","TBD",IF(BO4="N/A","N/A","W"&TEXT(WEEKNUM(BO4,21),"00")&" "&YEAR(BO4)))) | BQ4: Ing No Recibida | BT4: =IF(BS4="","",IF(BS4="TBD","TBD",IF(BS4="N/A","N/A","W"&TEXT(WEEKNUM(BS4,21),"00")&" "&YEAR(BS4)))) | BU4: Ing No Recibida | BX4: =IF(BW4="","",IF(BW4="TBD","TBD",IF(BW4="N/A","N/A","W"&TEXT(WEEKNUM(BW4,21),"00")&" "&YEAR(BW4)))) | BZ4: =IF(BY4="","",IF(BY4="TBD","TBD",IF(BY4="N/A","N/A","W"&TEXT(WEEKNUM(BY4,21),"00")&" "&YEAR(BY4)))) | CA4: Ing No Recibida 4G | CB4: 0 | CI4: =IF(CH4="","",IF(CH4="TBD","TBD",IF(CH4="N/A","N/A","W"&TEXT(WEEKNUM(CH4,21),"00")&" "&YEAR(CH4)))) | CK4: =IF(CJ4="","",IF(CJ4="TBD","TBD",IF(CJ4="N/A","N/A","W"&TEXT(WEEKNUM(CJ4,21),"00")&" "&YEAR(CJ4)))) | CL4: =+IF(CJ4="",0,(CJ4-CH4)) -> 0 | CM4: As Built No Recibido | CP4: =IF(CO4="","",IF(CO4="TBD","TBD",IF(CO4="N/A","N/A","W"&TEXT(WEEKNUM(CO4,21),"00")&" "&YEAR(CO4)))) | CQ4: As Built No Recibido | CT4: =IF(CS4="","",IF(CS4="TBD","TBD",IF(CS4="N/A","N/A","W"&TEXT(WEEKNUM(CS4,21),"00")&" "&YEAR(CS4)))) | CU4: As Built No Recibido | CX4: =IF(CW4="","",IF(CW4="TBD","TBD",IF(CW4="N/A","N/A","W"&TEXT(WEEKNUM(CW4,21),"00")&" "&YEAR(CW4)))) | CY4: As Built No Recibido | DB4: =IF(DA4="","",IF(DA4="TBD","TBD",IF(DA4="N/A","N/A","W"&TEXT(WEEKNUM(DA4,21),"00")&" "&YEAR(DA4)))) | DD4: =IF(DC4="","",IF(DC4="TBD","TBD",IF(DC4="N/A","N/A","W"&TEXT(WEEKNUM(DC4,21),"00")&" "&YEAR(DC4)))) | DE4: As Built No Recibido | DG4: Gabinete Huawei | DK4: FO | DL4: Poste | DQ4: Huawei | EB4: En Etapa de TSS 4G | EI4: 0 | EJ4: =K4&AY4&CA4&DE4&DT4&DW4 -> No VigenteTSS No Recibido 4GIng No Recibida 4GAs Built No Recibido
A5: =IFERROR(IF(VLOOKUP(B5,SEARCH!A:A,1,0)=B5,"OK",""),"") | B5: 07_168 | C5: Curico Rauquen | D5: 7 | E5: -34.951722 | F5: -71.192639 | G5: Maule | H5: Curicó | I5: Av. Los Carros, esquina Av Rauquén | J5: No Vigente | K5: No Vigente | L5: No aplica | O5: 0 | P5: BTS | Q5: 5-2-2025 Se informa por RF que sitios salen de plan 2024 (Correo Delfos) | R5: POSTE METALICO | S5: 18 | U5: 0 | V5: =IF(U5="","",IF(U5="TBD","TBD",IF(U5="N/A","N/A","W"&TEXT(WEEKNUM(U5,21),"00")&" "&YEAR(U5)))) -> W52 1900 | Y5: =IF(X5="","",IF(X5="TBD","TBD",IF(X5="N/A","N/A","W"&TEXT(WEEKNUM(X5,21),"00")&" "&YEAR(X5)))) | AB5: =+IF(Z5="",0,AA5-Z5) -> 0 | AC5: TSS No Recibido | AF5: =IF(AE5="","",IF(AE5="TBD","TBD",IF(AE5="N/A","N/A","W"&TEXT(WEEKNUM(AE5,21),"00")&" "&YEAR(AE5)))) | AG5: TSS No Recibido | AJ5: =IF(AI5="","",IF(AI5="TBD","TBD",IF(AI5="N/A","N/A","W"&TEXT(WEEKNUM(AI5,21),"00")&" "&YEAR(AI5)))) | AK5: TSS No Recibido | AN5: =IF(AM5="","",IF(AM5="TBD","TBD",IF(AM5="N/A","N/A","W"&TEXT(WEEKNUM(AM5,21),"00")&" "&YEAR(AM5)))) | AO5: TSS No Recibido | AR5: =IF(AQ5="","",IF(AQ5="TBD","TBD",IF(AQ5="N/A","N/A","W"&TEXT(WEEKNUM(AQ5,21),"00")&" "&YEAR(AQ5)))) | AX5: =IF(AW5="","",IF(AW5="TBD","TBD",IF(AW5="N/A","N/A","W"&TEXT(WEEKNUM(AW5,21),"00")&" "&YEAR(AW5)))) | AY5: TSS No Recibido 4G | AZ5: Pendiente FC | BA5: Contrato No Firmado | BE5: =IF(BD5="","",IF(BD5="TBD","TBD",IF(BD5="N/A","N/A","W"&TEXT(WEEKNUM(BD5,21),"00")&" "&YEAR(BD5)))) | BG5: =IF(BF5="","",IF(BF5="TBD","TBD",IF(BF5="N/A","N/A","W"&TEXT(WEEKNUM(BF5,21),"00")&" "&YEAR(BF5)))) | BH5: =+IF(BF5="",0,(BF5-BD5)) -> 0 | BI5: Ing No Recibida | BL5: =IF(BK5="","",IF(BK5="TBD","TBD",IF(BK5="N/A","N/A","W"&TEXT(WEEKNUM(BK5,21),"00")&" "&YEAR(BK5)))) | BM5: Ing No Recibida | BP5: =IF(BO5="","",IF(BO5="TBD","TBD",IF(BO5="N/A","N/A","W"&TEXT(WEEKNUM(BO5,21),"00")&" "&YEAR(BO5)))) | BQ5: Ing No Recibida | BT5: =IF(BS5="","",IF(BS5="TBD","TBD",IF(BS5="N/A","N/A","W"&TEXT(WEEKNUM(BS5,21),"00")&" "&YEAR(BS5)))) | BU5: Ing No Recibida | BX5: =IF(BW5="","",IF(BW5="TBD","TBD",IF(BW5="N/A","N/A","W"&TEXT(WEEKNUM(BW5,21),"00")&" "&YEAR(BW5)))) | BZ5: =IF(BY5="","",IF(BY5="TBD","TBD",IF(BY5="N/A","N/A","W"&TEXT(WEEKNUM(BY5,21),"00")&" "&YEAR(BY5)))) | CA5: Ing No Recibida 4G | CB5: 0 | CI5: =IF(CH5="","",IF(CH5="TBD","TBD",IF(CH5="N/A","N/A","W"&TEXT(WEEKNUM(CH5,21),"00")&" "&YEAR(CH5)))) | CK5: =IF(CJ5="","",IF(CJ5="TBD","TBD",IF(CJ5="N/A","N/A","W"&TEXT(WEEKNUM(CJ5,21),"00")&" "&YEAR(CJ5)))) | CL5: =+IF(CJ5="",0,(CJ5-CH5)) -> 0 | CM5: As Built No Recibido | CP5: =IF(CO5="","",IF(CO5="TBD","TBD",IF(CO5="N/A","N/A","W"&TEXT(WEEKNUM(CO5,21),"00")&" "&YEAR(CO5)))) | CQ5: As Built No Recibido | CT5: =IF(CS5="","",IF(CS5="TBD","TBD",IF(CS5="N/A","N/A","W"&TEXT(WEEKNUM(CS5,21),"00")&" "&YEAR(CS5)))) | CU5: As Built No Recibido | CX5: =IF(CW5="","",IF(CW5="TBD","TBD",IF(CW5="N/A","N/A","W"&TEXT(WEEKNUM(CW5,21),"00")&" "&YEAR(CW5)))) | CY5: As Built No Recibido | DB5: =IF(DA5="","",IF(DA5="TBD","TBD",IF(DA5="N/A","N/A","W"&TEXT(WEEKNUM(DA5,21),"00")&" "&YEAR(DA5)))) | DD5: =IF(DC5="","",IF(DC5="TBD","TBD",IF(DC5="N/A","N/A","W"&TEXT(WEEKNUM(DC5,21),"00")&" "&YEAR(DC5)))) | DE5: As Built No Recibido | DG5: Gabinete Huawei | DK5: FO | DL5: Poste | DQ5: Huawei | EB5: En Etapa de TSS 4G | EI5: 0 | EJ5: =K5&AY5&CA5&DE5&DT5&DW5 -> No VigenteTSS No Recibido 4GIng No Recibida 4GAs Built No Recibido
A6: =IFERROR(IF(VLOOKUP(B6,SEARCH!A:A,1,0)=B6,"OK",""),"") | B6: 53i_390 | C6: Banco Bci - Seguros Generales | D6: 13 | E6: -33.405994 | F6: -70.568975 | G6: Metropolitana de Santiago | H6: LAS CONDES | J6: Indoor | K6: No Vigente | L6: No aplica | O6: 0 | P6: 0 | R6: Indoor - B2B | V6: =IF(U6="","",IF(U6="TBD","TBD",IF(U6="N/A","N/A","W"&TEXT(WEEKNUM(U6,21),"00")&" "&YEAR(U6)))) | Y6: =IF(X6="","",IF(X6="TBD","TBD",IF(X6="N/A","N/A","W"&TEXT(WEEKNUM(X6,21),"00")&" "&YEAR(X6)))) | AB6: =+IF(Z6="",0,AA6-Z6) -> 0 | AC6: TSS No Recibido | AF6: =IF(AE6="","",IF(AE6="TBD","TBD",IF(AE6="N/A","N/A","W"&TEXT(WEEKNUM(AE6,21),"00")&" "&YEAR(AE6)))) | AG6: TSS No Recibido | AJ6: =IF(AI6="","",IF(AI6="TBD","TBD",IF(AI6="N/A","N/A","W"&TEXT(WEEKNUM(AI6,21),"00")&" "&YEAR(AI6)))) | AK6: TSS No Recibido | AN6: =IF(AM6="","",IF(AM6="TBD","TBD",IF(AM6="N/A","N/A","W"&TEXT(WEEKNUM(AM6,21),"00")&" "&YEAR(AM6)))) | AO6: TSS No Recibido | AR6: =IF(AQ6="","",IF(AQ6="TBD","TBD",IF(AQ6="N/A","N/A","W"&TEXT(WEEKNUM(AQ6,21),"00")&" "&YEAR(AQ6)))) | AX6: =IF(AW6="","",IF(AW6="TBD","TBD",IF(AW6="N/A","N/A","W"&TEXT(WEEKNUM(AW6,21),"00")&" "&YEAR(AW6)))) | AY6: TSS No Recibido 4G | AZ6: Pendiente FC | BA6: Contrato No Firmado | BE6: =IF(BD6="","",IF(BD6="TBD","TBD",IF(BD6="N/A","N/A","W"&TEXT(WEEKNUM(BD6,21),"00")&" "&YEAR(BD6)))) | BG6: =IF(BF6="","",IF(BF6="TBD","TBD",IF(BF6="N/A","N/A","W"&TEXT(WEEKNUM(BF6,21),"00")&" "&YEAR(BF6)))) | BH6: =+IF(BF6="",0,(BF6-BD6)) -> 0 | BI6: Ing No Recibida | BL6: =IF(BK6="","",IF(BK6="TBD","TBD",IF(BK6="N/A","N/A","W"&TEXT(WEEKNUM(BK6,21),"00")&" "&YEAR(BK6)))) | BM6: Ing No Recibida | BP6: =IF(BO6="","",IF(BO6="TBD","TBD",IF(BO6="N/A","N/A","W"&TEXT(WEEKNUM(BO6,21),"00")&" "&YEAR(BO6)))) | BQ6: Ing No Recibida | BT6: =IF(BS6="","",IF(BS6="TBD","TBD",IF(BS6="N/A","N/A","W"&TEXT(WEEKNUM(BS6,21),"00")&" "&YEAR(BS6)))) | BU6: Ing No Recibida | BX6: =IF(BW6="","",IF(BW6="TBD","TBD",IF(BW6="N/A","N/A","W"&TEXT(WEEKNUM(BW6,21),"00")&" "&YEAR(BW6)))) | BZ6: =IF(BY6="","",IF(BY6="TBD","TBD",IF(BY6="N/A","N/A","W"&TEXT(WEEKNUM(BY6,21),"00")&" "&YEAR(BY6)))) | CA6: Ing No Recibida 4G | CB6: 0 | CI6: =IF(CH6="","",IF(CH6="TBD","TBD",IF(CH6="N/A","N/A","W"&TEXT(WEEKNUM(CH6,21),"00")&" "&YEAR(CH6)))) | CK6: =IF(CJ6="","",IF(CJ6="TBD","TBD",IF(CJ6="N/A","N/A","W"&TEXT(WEEKNUM(CJ6,21),"00")&" "&YEAR(CJ6)))) | CL6: =+IF(CJ6="",0,(CJ6-CH6)) -> 0 | CM6: As Built No Recibido | CP6: =IF(CO6="","",IF(CO6="TBD","TBD",IF(CO6="N/A","N/A","W"&TEXT(WEEKNUM(CO6,21),"00")&" "&YEAR(CO6)))) | CQ6: As Built No Recibido | CT6: =IF(CS6="","",IF(CS6="TBD","TBD",IF(CS6="N/A","N/A","W"&TEXT(WEEKNUM(CS6,21),"00")&" "&YEAR(CS6)))) | CU6: As Built No Recibido | CX6: =IF(CW6="","",IF(CW6="TBD","TBD",IF(CW6="N/A","N/A","W"&TEXT(WEEKNUM(CW6,21),"00")&" "&YEAR(CW6)))) | CY6: As Built No Recibido | DB6: =IF(DA6="","",IF(DA6="TBD","TBD",IF(DA6="N/A","N/A","W"&TEXT(WEEKNUM(DA6,21),"00")&" "&YEAR(DA6)))) | DD6: =IF(DC6="","",IF(DC6="TBD","TBD",IF(DC6="N/A","N/A","W"&TEXT(WEEKNUM(DC6,21),"00")&" "&YEAR(DC6)))) | DE6: As Built No Recibido | DG6: Por Definir | DK6: FO | DL6: Pendiente | DQ6: ZTE | DY6: 0 | DZ6: 0 | EA6: 0 | EB6: En Etapa de TSS 4G | EI6: 0 | EJ6: =K6&AY6&CA6&DE6&DT6&DW6 -> No VigenteTSS No Recibido 4GIng No Recibida 4GAs Built No Recibido
A7: =IFERROR(IF(VLOOKUP(B7,SEARCH!A:A,1,0)=B7,"OK",""),"") | B7: 53i_393 | C7: Holding Laboratorio Ballerina | D7: 13 | E7: -33.422743 | F7: -70.621951 | G7: Metropolitana de Santiago | H7: PROVIDENCIA | J7: Indoor | K7: No Vigente | L7: No aplica | O7: 0 | P7: 0 | Q7: Sitio descartado por B2B | R7: Indoor - B2B | U7: 0 | V7: =IF(U7="","",IF(U7="TBD","TBD",IF(U7="N/A","N/A","W"&TEXT(WEEKNUM(U7,21),"00")&" "&YEAR(U7)))) -> W52 1900 | Y7: =IF(X7="","",IF(X7="TBD","TBD",IF(X7="N/A","N/A","W"&TEXT(WEEKNUM(X7,21),"00")&" "&YEAR(X7)))) | AB7: =+IF(Z7="",0,AA7-Z7) -> 0 | AC7: TSS No Recibido | AF7: =IF(AE7="","",IF(AE7="TBD","TBD",IF(AE7="N/A","N/A","W"&TEXT(WEEKNUM(AE7,21),"00")&" "&YEAR(AE7)))) | AG7: TSS No Recibido | AJ7: =IF(AI7="","",IF(AI7="TBD","TBD",IF(AI7="N/A","N/A","W"&TEXT(WEEKNUM(AI7,21),"00")&" "&YEAR(AI7)))) | AK7: TSS No Recibido | AN7: =IF(AM7="","",IF(AM7="TBD","TBD",IF(AM7="N/A","N/A","W"&TEXT(WEEKNUM(AM7,21),"00")&" "&YEAR(AM7)))) | AO7: TSS No Recibido | AR7: =IF(AQ7="","",IF(AQ7="TBD","TBD",IF(AQ7="N/A","N/A","W"&TEXT(WEEKNUM(AQ7,21),"00")&" "&YEAR(AQ7)))) | AX7: =IF(AW7="","",IF(AW7="TBD","TBD",IF(AW7="N/A","N/A","W"&TEXT(WEEKNUM(AW7,21),"00")&" "&YEAR(AW7)))) | AY7: TSS No Recibido 4G | AZ7: Pendiente FC | BA7: Contrato No Firmado | BE7: =IF(BD7="","",IF(BD7="TBD","TBD",IF(BD7="N/A","N/A","W"&TEXT(WEEKNUM(BD7,21),"00")&" "&YEAR(BD7)))) | BG7: =IF(BF7="","",IF(BF7="TBD","TBD",IF(BF7="N/A","N/A","W"&TEXT(WEEKNUM(BF7,21),"00")&" "&YEAR(BF7)))) | BH7: =+IF(BF7="",0,(BF7-BD7)) -> 0 | BI7: Ing No Recibida | BL7: =IF(BK7="","",IF(BK7="TBD","TBD",IF(BK7="N/A","N/A","W"&TEXT(WEEKNUM(BK7,21),"00")&" "&YEAR(BK7)))) | BM7: Ing No Recibida | BP7: =IF(BO7="","",IF(BO7="TBD","TBD",IF(BO7="N/A","N/A","W"&TEXT(WEEKNUM(BO7,21),"00")&" "&YEAR(BO7)))) | BQ7: Ing No Recibida | BT7: =IF(BS7="","",IF(BS7="TBD","TBD",IF(BS7="N/A","N/A","W"&TEXT(WEEKNUM(BS7,21),"00")&" "&YEAR(BS7)))) | BU7: Ing No Recibida | BX7: =IF(BW7="","",IF(BW7="TBD","TBD",IF(BW7="N/A","N/A","W"&TEXT(WEEKNUM(BW7,21),"00")&" "&YEAR(BW7)))) | BZ7: =IF(BY7="","",IF(BY7="TBD","TBD",IF(BY7="N/A","N/A","W"&TEXT(WEEKNUM(BY7,21),"00")&" "&YEAR(BY7)))) | CA7: Ing No Recibida 4G | CB7: 0 | CI7: =IF(CH7="","",IF(CH7="TBD","TBD",IF(CH7="N/A","N/A","W"&TEXT(WEEKNUM(CH7,21),"00")&" "&YEAR(CH7)))) | CK7: =IF(CJ7="","",IF(CJ7="TBD","TBD",IF(CJ7="N/A","N/A","W"&TEXT(WEEKNUM(CJ7,21),"00")&" "&YEAR(CJ7)))) | CL7: =+IF(CJ7="",0,(CJ7-CH7)) -> 0 | CM7: As Built No Recibido | CP7: =IF(CO7="","",IF(CO7="TBD","TBD",IF(CO7="N/A","N/A","W"&TEXT(WEEKNUM(CO7,21),"00")&" "&YEAR(CO7)))) | CQ7: As Built No Recibido | CT7: =IF(CS7="","",IF(CS7="TBD","TBD",IF(CS7="N/A","N/A","W"&TEXT(WEEKNUM(CS7,21),"00")&" "&YEAR(CS7)))) | CU7: As Built No Recibido | CX7: =IF(CW7="","",IF(CW7="TBD","TBD",IF(CW7="N/A","N/A","W"&TEXT(WEEKNUM(CW7,21),"00")&" "&YEAR(CW7)))) | CY7: As Built No Recibido | DB7: =IF(DA7="","",IF(DA7="TBD","TBD",IF(DA7="N/A","N/A","W"&TEXT(WEEKNUM(DA7,21),"00")&" "&YEAR(DA7)))) | DD7: =IF(DC7="","",IF(DC7="TBD","TBD",IF(DC7="N/A","N/A","W"&TEXT(WEEKNUM(DC7,21),"00")&" "&YEAR(DC7)))) | DE7: As Built No Recibido | DG7: Por Definir | DK7: FO | DL7: Pendiente | DQ7: ZTE | DY7: 0 | DZ7: 0 | EA7: 0 | EB7: En Etapa de TSS 4G | EI7: 0 | EJ7: =K7&AY7&CA7&DE7&DT7&DW7 -> No VigenteTSS No Recibido 4GIng No Recibida 4GAs Built No Recibido
A8: =IFERROR(IF(VLOOKUP(B8,SEARCH!A:A,1,0)=B8,"OK",""),"") | B8: 53i_396 | C8: INVERSIONES QUILAPILUN S.A. | D8: 13 | E8: -33.378032 | F8: -70.742595 | G8: Metropolitana de Santiago | H8: QUILICURA | J8: Indoor | K8: No Vigente | L8: No aplica | O8: 0 | P8: 0 | Q8: Sitio descartado por B2B | R8: Indoor - B2B | U8: 0 | V8: =IF(U8="","",IF(U8="TBD","TBD",IF(U8="N/A","N/A","W"&TEXT(WEEKNUM(U8,21),"00")&" "&YEAR(U8)))) -> W52 1900 | Y8: =IF(X8="","",IF(X8="TBD","TBD",IF(X8="N/A","N/A","W"&TEXT(WEEKNUM(X8,21),"00")&" "&YEAR(X8)))) | AB8: =+IF(Z8="",0,AA8-Z8) -> 0 | AC8: TSS No Recibido | AF8: =IF(AE8="","",IF(AE8="TBD","TBD",IF(AE8="N/A","N/A","W"&TEXT(WEEKNUM(AE8,21),"00")&" "&YEAR(AE8)))) | AG8: TSS No Recibido | AJ8: =IF(AI8="","",IF(AI8="TBD","TBD",IF(AI8="N/A","N/A","W"&TEXT(WEEKNUM(AI8,21),"00")&" "&YEAR(AI8)))) | AK8: TSS No Recibido | AN8: =IF(AM8="","",IF(AM8="TBD","TBD",IF(AM8="N/A","N/A","W"&TEXT(WEEKNUM(AM8,21),"00")&" "&YEAR(AM8)))) | AO8: TSS No Recibido | AR8: =IF(AQ8="","",IF(AQ8="TBD","TBD",IF(AQ8="N/A","N/A","W"&TEXT(WEEKNUM(AQ8,21),"00")&" "&YEAR(AQ8)))) | AX8: =IF(AW8="","",IF(AW8="TBD","TBD",IF(AW8="N/A","N/A","W"&TEXT(WEEKNUM(AW8,21),"00")&" "&YEAR(AW8)))) | AY8: TSS No Recibido 4G | AZ8: Pendiente FC | BA8: Contrato No Firmado | BE8: =IF(BD8="","",IF(BD8="TBD","TBD",IF(BD8="N/A","N/A","W"&TEXT(WEEKNUM(BD8,21),"00")&" "&YEAR(BD8)))) | BG8: =IF(BF8="","",IF(BF8="TBD","TBD",IF(BF8="N/A","N/A","W"&TEXT(WEEKNUM(BF8,21),"00")&" "&YEAR(BF8)))) | BH8: =+IF(BF8="",0,(BF8-BD8)) -> 0 | BI8: Ing No Recibida | BL8: =IF(BK8="","",IF(BK8="TBD","TBD",IF(BK8="N/A","N/A","W"&TEXT(WEEKNUM(BK8,21),"00")&" "&YEAR(BK8)))) | BM8: Ing No Recibida | BP8: =IF(BO8="","",IF(BO8="TBD","TBD",IF(BO8="N/A","N/A","W"&TEXT(WEEKNUM(BO8,21),"00")&" "&YEAR(BO8)))) | BQ8: Ing No Recibida | BT8: =IF(BS8="","",IF(BS8="TBD","TBD",IF(BS8="N/A","N/A","W"&TEXT(WEEKNUM(BS8,21),"00")&" "&YEAR(BS8)))) | BU8: Ing No Recibida | BX8: =IF(BW8="","",IF(BW8="TBD","TBD",IF(BW8="N/A","N/A","W"&TEXT(WEEKNUM(BW8,21),"00")&" "&YEAR(BW8)))) | BZ8: =IF(BY8="","",IF(BY8="TBD","TBD",IF(BY8="N/A","N/A","W"&TEXT(WEEKNUM(BY8,21),"00")&" "&YEAR(BY8)))) | CA8: Ing No Recibida 4G | CB8: 0 | CI8: =IF(CH8="","",IF(CH8="TBD","TBD",IF(CH8="N/A","N/A","W"&TEXT(WEEKNUM(CH8,21),"00")&" "&YEAR(CH8)))) | CK8: =IF(CJ8="","",IF(CJ8="TBD","TBD",IF(CJ8="N/A","N/A","W"&TEXT(WEEKNUM(CJ8,21),"00")&" "&YEAR(CJ8)))) | CL8: =+IF(CJ8="",0,(CJ8-CH8)) -> 0 | CM8: As Built No Recibido | CP8: =IF(CO8="","",IF(CO8="TBD","TBD",IF(CO8="N/A","N/A","W"&TEXT(WEEKNUM(CO8,21),"00")&" "&YEAR(CO8)))) | CQ8: As Built No Recibido | CT8: =IF(CS8="","",IF(CS8="TBD","TBD",IF(CS8="N/A","N/A","W"&TEXT(WEEKNUM(CS8,21),"00")&" "&YEAR(CS8)))) | CU8: As Built No Recibido | CX8: =IF(CW8="","",IF(CW8="TBD","TBD",IF(CW8="N/A","N/A","W"&TEXT(WEEKNUM(CW8,21),"00")&" "&YEAR(CW8)))) | CY8: As Built No Recibido | DB8: =IF(DA8="","",IF(DA8="TBD","TBD",IF(DA8="N/A","N/A","W"&TEXT(WEEKNUM(DA8,21),"00")&" "&YEAR(DA8)))) | DD8: =IF(DC8="","",IF(DC8="TBD","TBD",IF(DC8="N/A","N/A","W"&TEXT(WEEKNUM(DC8,21),"00")&" "&YEAR(DC8)))) | DE8: As Built No Recibido | DG8: Por Definir | DK8: FO | DL8: Pendiente | DQ8: ZTE | DY8: 0 | DZ8: 0 | EA8: 0 | EB8: En Etapa de TSS 4G | EI8: 0 | EJ8: =K8&AY8&CA8&DE8&DT8&DW8 -> No VigenteTSS No Recibido 4GIng No Recibida 4GAs Built No Recibido
A9: =IFERROR(IF(VLOOKUP(B9,SEARCH!A:A,1,0)=B9,"OK",""),"") | B9: 16i_121 | C9: Jumbo - Longitudinal Chillán | D9: 16 | E9: -36.595668 | F9: -72.107283 | G9: Ñuble | H9: Chillan | J9: Indoor | K9: No Vigente | L9: No aplica | O9: 0 | P9: 0 | R9: Indoor - B2B | U9: 0 | V9: =IF(U9="","",IF(U9="TBD","TBD",IF(U9="N/A","N/A","W"&TEXT(WEEKNUM(U9,21),"00")&" "&YEAR(U9)))) -> W52 1900 | Y9: =IF(X9="","",IF(X9="TBD","TBD",IF(X9="N/A","N/A","W"&TEXT(WEEKNUM(X9,21),"00")&" "&YEAR(X9)))) | AB9: =+IF(Z9="",0,AA9-Z9) -> 0 | AC9: TSS No Recibido | AF9: =IF(AE9="","",IF(AE9="TBD","TBD",IF(AE9="N/A","N/A","W"&TEXT(WEEKNUM(AE9,21),"00")&" "&YEAR(AE9)))) | AG9: TSS No Recibido | AJ9: =IF(AI9="","",IF(AI9="TBD","TBD",IF(AI9="N/A","N/A","W"&TEXT(WEEKNUM(AI9,21),"00")&" "&YEAR(AI9)))) | AK9: TSS No Recibido | AN9: =IF(AM9="","",IF(AM9="TBD","TBD",IF(AM9="N/A","N/A","W"&TEXT(WEEKNUM(AM9,21),"00")&" "&YEAR(AM9)))) | AO9: TSS No Recibido | AR9: =IF(AQ9="","",IF(AQ9="TBD","TBD",IF(AQ9="N/A","N/A","W"&TEXT(WEEKNUM(AQ9,21),"00")&" "&YEAR(AQ9)))) | AX9: =IF(AW9="","",IF(AW9="TBD","TBD",IF(AW9="N/A","N/A","W"&TEXT(WEEKNUM(AW9,21),"00")&" "&YEAR(AW9)))) | AY9: TSS No Recibido 4G | AZ9: Pendiente FC | BA9: Contrato No Firmado | BE9: =IF(BD9="","",IF(BD9="TBD","TBD",IF(BD9="N/A","N/A","W"&TEXT(WEEKNUM(BD9,21),"00")&" "&YEAR(BD9)))) | BG9: =IF(BF9="","",IF(BF9="TBD","TBD",IF(BF9="N/A","N/A","W"&TEXT(WEEKNUM(BF9,21),"00")&" "&YEAR(BF9)))) | BH9: =+IF(BF9="",0,(BF9-BD9)) -> 0 | BI9: Ing No Recibida | BL9: =IF(BK9="","",IF(BK9="TBD","TBD",IF(BK9="N/A","N/A","W"&TEXT(WEEKNUM(BK9,21),"00")&" "&YEAR(BK9)))) | BM9: Ing No Recibida | BP9: =IF(BO9="","",IF(BO9="TBD","TBD",IF(BO9="N/A","N/A","W"&TEXT(WEEKNUM(BO9,21),"00")&" "&YEAR(BO9)))) | BQ9: Ing No Recibida | BT9: =IF(BS9="","",IF(BS9="TBD","TBD",IF(BS9="N/A","N/A","W"&TEXT(WEEKNUM(BS9,21),"00")&" "&YEAR(BS9)))) | BU9: Ing No Recibida | BX9: =IF(BW9="","",IF(BW9="TBD","TBD",IF(BW9="N/A","N/A","W"&TEXT(WEEKNUM(BW9,21),"00")&" "&YEAR(BW9)))) | BZ9: =IF(BY9="","",IF(BY9="TBD","TBD",IF(BY9="N/A","N/A","W"&TEXT(WEEKNUM(BY9,21),"00")&" "&YEAR(BY9)))) | CA9: Ing No Recibida 4G | CB9: 0 | CI9: =IF(CH9="","",IF(CH9="TBD","TBD",IF(CH9="N/A","N/A","W"&TEXT(WEEKNUM(CH9,21),"00")&" "&YEAR(CH9)))) | CK9: =IF(CJ9="","",IF(CJ9="TBD","TBD",IF(CJ9="N/A","N/A","W"&TEXT(WEEKNUM(CJ9,21),"00")&" "&YEAR(CJ9)))) | CL9: =+IF(CJ9="",0,(CJ9-CH9)) -> 0 | CM9: As Built No Recibido | CP9: =IF(CO9="","",IF(CO9="TBD","TBD",IF(CO9="N/A","N/A","W"&TEXT(WEEKNUM(CO9,21),"00")&" "&YEAR(CO9)))) | CQ9: As Built No Recibido | CT9: =IF(CS9="","",IF(CS9="TBD","TBD",IF(CS9="N/A","N/A","W"&TEXT(WEEKNUM(CS9,21),"00")&" "&YEAR(CS9)))) | CU9: As Built No Recibido | CX9: =IF(CW9="","",IF(CW9="TBD","TBD",IF(CW9="N/A","N/A","W"&TEXT(WEEKNUM(CW9,21),"00")&" "&YEAR(CW9)))) | CY9: As Built No Recibido | DB9: =IF(DA9="","",IF(DA9="TBD","TBD",IF(DA9="N/A","N/A","W"&TEXT(WEEKNUM(DA9,21),"00")&" "&YEAR(DA9)))) | DD9: =IF(DC9="","",IF(DC9="TBD","TBD",IF(DC9="N/A","N/A","W"&TEXT(WEEKNUM(DC9,21),"00")&" "&YEAR(DC9)))) | DE9: As Built No Recibido | DG9: Por Definir | DK9: FO | DL9: Pendiente | DQ9: Huawei | DY9: 0 | DZ9: 0 | EA9: 0 | EB9: En Etapa de TSS 4G | EI9: 0 | EJ9: =K9&AY9&CA9&DE9&DT9&DW9 -> No VigenteTSS No Recibido 4GIng No Recibida 4GAs Built No Recibido
A10: =IFERROR(IF(VLOOKUP(B10,SEARCH!A:A,1,0)=B10,"OK",""),"") | B10: 53i_405 | C10: Polytex S.A | D10: 13 | E10: -33.283105 | F10: -70.736448 | G10: Metropolitana de Santiago | H10: COLINA | I10: Panamericana Norte 21000, Colina | J10: Indoor | K10: No Vigente | L10: No aplica | O10: 0 | P10: 0 | Q10: Sitio descartado por B2B | R10: Indoor - B2B | U10: 0 | V10: =IF(U10="","",IF(U10="TBD","TBD",IF(U10="N/A","N/A","W"&TEXT(WEEKNUM(U10,21),"00")&" "&YEAR(U10)))) -> W52 1900 | Y10: =IF(X10="","",IF(X10="TBD","TBD",IF(X10="N/A","N/A","W"&TEXT(WEEKNUM(X10,21),"00")&" "&YEAR(X10)))) | AB10: =+IF(Z10="",0,AA10-Z10) -> 0 | AC10: TSS No Recibido | AF10: =IF(AE10="","",IF(AE10="TBD","TBD",IF(AE10="N/A","N/A","W"&TEXT(WEEKNUM(AE10,21),"00")&" "&YEAR(AE10)))) | AG10: TSS No Recibido | AJ10: =IF(AI10="","",IF(AI10="TBD","TBD",IF(AI10="N/A","N/A","W"&TEXT(WEEKNUM(AI10,21),"00")&" "&YEAR(AI10)))) | AK10: TSS No Recibido | AN10: =IF(AM10="","",IF(AM10="TBD","TBD",IF(AM10="N/A","N/A","W"&TEXT(WEEKNUM(AM10,21),"00")&" "&YEAR(AM10)))) | AO10: TSS No Recibido | AR10: =IF(AQ10="","",IF(AQ10="TBD","TBD",IF(AQ10="N/A","N/A","W"&TEXT(WEEKNUM(AQ10,21),"00")&" "&YEAR(AQ10)))) | AX10: =IF(AW10="","",IF(AW10="TBD","TBD",IF(AW10="N/A","N/A","W"&TEXT(WEEKNUM(AW10,21),"00")&" "&YEAR(AW10)))) | AY10: TSS No Recibido 4G | AZ10: Pendiente FC | BA10: Contrato No Firmado | BE10: =IF(BD10="","",IF(BD10="TBD","TBD",IF(BD10="N/A","N/A","W"&TEXT(WEEKNUM(BD10,21),"00")&" "&YEAR(BD10)))) | BG10: =IF(BF10="","",IF(BF10="TBD","TBD",IF(BF10="N/A","N/A","W"&TEXT(WEEKNUM(BF10,21),"00")&" "&YEAR(BF10)))) | BH10: =+IF(BF10="",0,(BF10-BD10)) -> 0 | BI10: Ing No Recibida | BL10: =IF(BK10="","",IF(BK10="TBD","TBD",IF(BK10="N/A","N/A","W"&TEXT(WEEKNUM(BK10,21),"00")&" "&YEAR(BK10)))) | BM10: Ing No Recibida | BP10: =IF(BO10="","",IF(BO10="TBD","TBD",IF(BO10="N/A","N/A","W"&TEXT(WEEKNUM(BO10,21),"00")&" "&YEAR(BO10)))) | BQ10: Ing No Recibida | BT10: =IF(BS10="","",IF(BS10="TBD","TBD",IF(BS10="N/A","N/A","W"&TEXT(WEEKNUM(BS10,21),"00")&" "&YEAR(BS10)))) | BU10: Ing No Recibida | BX10: =IF(BW10="","",IF(BW10="TBD","TBD",IF(BW10="N/A","N/A","W"&TEXT(WEEKNUM(BW10,21),"00")&" "&YEAR(BW10)))) | BZ10: =IF(BY10="","",IF(BY10="TBD","TBD",IF(BY10="N/A","N/A","W"&TEXT(WEEKNUM(BY10,21),"00")&" "&YEAR(BY10)))) | CA10: Ing No Recibida 4G | CB10: 0 | CI10: =IF(CH10="","",IF(CH10="TBD","TBD",IF(CH10="N/A","N/A","W"&TEXT(WEEKNUM(CH10,21),"00")&" "&YEAR(CH10)))) | CK10: =IF(CJ10="","",IF(CJ10="TBD","TBD",IF(CJ10="N/A","N/A","W"&TEXT(WEEKNUM(CJ10,21),"00")&" "&YEAR(CJ10)))) | CL10: =+IF(CJ10="",0,(CJ10-CH10)) -> 0 | CM10: As Built No Recibido | CP10: =IF(CO10="","",IF(CO10="TBD","TBD",IF(CO10="N/A","N/A","W"&TEXT(WEEKNUM(CO10,21),"00")&" "&YEAR(CO10)))) | CQ10: As Built No Recibido | CT10: =IF(CS10="","",IF(CS10="TBD","TBD",IF(CS10="N/A","N/A","W"&TEXT(WEEKNUM(CS10,21),"00")&" "&YEAR(CS10)))) | CU10: As Built No Recibido | CX10: =IF(CW10="","",IF(CW10="TBD","TBD",IF(CW10="N/A","N/A","W"&TEXT(WEEKNUM(CW10,21),"00")&" "&YEAR(CW10)))) | CY10: As Built No Recibido | DB10: =IF(DA10="","",IF(DA10="TBD","TBD",IF(DA10="N/A","N/A","W"&TEXT(WEEKNUM(DA10,21),"00")&" "&YEAR(DA10)))) | DD10: =IF(DC10="","",IF(DC10="TBD","TBD",IF(DC10="N/A","N/A","W"&TEXT(WEEKNUM(DC10,21),"00")&" "&YEAR(DC10)))) | DE10: As Built No Recibido | DG10: Por Definir | DK10: FO | DL10: Pendiente | DQ10: ZTE | DY10: 0 | DZ10: 0 | EA10: 0 | EB10: En Etapa de TSS 4G | EI10: 0 | EJ10: =K10&AY10&CA10&DE10&DT10&DW10 -> No VigenteTSS No Recibido 4GIng No Recibida 4GAs Built No Recibido
A11: =IFERROR(IF(VLOOKUP(B11,SEARCH!A:A,1,0)=B11,"OK",""),"") | B11: 07_856 | C11: Villa Los Niches Ruta J-65 | D11: 7 | E11: -35.074722 | F11: -71.151778 | G11: Maule | H11: Curicó | I11: Ruta J-65, Km 11.8 | J11: Fase 1 - On Hold RF | K11: No Vigente | L11: No aplica | M11: TBD | O11: 0 | P11: BTS | Q11: 5-2-2025 Se informa por RF que sitios salen de plan 2024 (Correo Delfos) | R11: POSTE METALICO | S11: 18 | U11: 0 | V11: =IF(U11="","",IF(U11="TBD","TBD",IF(U11="N/A","N/A","W"&TEXT(WEEKNUM(U11,21),"00")&" "&YEAR(U11)))) -> W52 1900 | Y11: =IF(X11="","",IF(X11="TBD","TBD",IF(X11="N/A","N/A","W"&TEXT(WEEKNUM(X11,21),"00")&" "&YEAR(X11)))) | AB11: =+IF(Z11="",0,AA11-Z11) -> 0 | AC11: TSS No Recibido | AF11: =IF(AE11="","",IF(AE11="TBD","TBD",IF(AE11="N/A","N/A","W"&TEXT(WEEKNUM(AE11,21),"00")&" "&YEAR(AE11)))) | AG11: TSS No Recibido | AJ11: =IF(AI11="","",IF(AI11="TBD","TBD",IF(AI11="N/A","N/A","W"&TEXT(WEEKNUM(AI11,21),"00")&" "&YEAR(AI11)))) | AK11: TSS No Recibido | AN11: =IF(AM11="","",IF(AM11="TBD","TBD",IF(AM11="N/A","N/A","W"&TEXT(WEEKNUM(AM11,21),"00")&" "&YEAR(AM11)))) | AO11: TSS No Recibido | AR11: =IF(AQ11="","",IF(AQ11="TBD","TBD",IF(AQ11="N/A","N/A","W"&TEXT(WEEKNUM(AQ11,21),"00")&" "&YEAR(AQ11)))) | AX11: =IF(AW11="","",IF(AW11="TBD","TBD",IF(AW11="N/A","N/A","W"&TEXT(WEEKNUM(AW11,21),"00")&" "&YEAR(AW11)))) | AY11: TSS No Recibido 4G | AZ11: Pendiente FC | BA11: Contrato No Firmado | BE11: =IF(BD11="","",IF(BD11="TBD","TBD",IF(BD11="N/A","N/A","W"&TEXT(WEEKNUM(BD11,21),"00")&" "&YEAR(BD11)))) | BG11: =IF(BF11="","",IF(BF11="TBD","TBD",IF(BF11="N/A","N/A","W"&TEXT(WEEKNUM(BF11,21),"00")&" "&YEAR(BF11)))) | BH11: =+IF(BF11="",0,(BF11-BD11)) -> 0 | BI11: Ing No Recibida | BL11: =IF(BK11="","",IF(BK11="TBD","TBD",IF(BK11="N/A","N/A","W"&TEXT(WEEKNUM(BK11,21),"00")&" "&YEAR(BK11)))) | BM11: Ing No Recibida | BP11: =IF(BO11="","",IF(BO11="TBD","TBD",IF(BO11="N/A","N/A","W"&TEXT(WEEKNUM(BO11,21),"00")&" "&YEAR(BO11)))) | BQ11: Ing No Recibida | BT11: =IF(BS11="","",IF(BS11="TBD","TBD",IF(BS11="N/A","N/A","W"&TEXT(WEEKNUM(BS11,21),"00")&" "&YEAR(BS11)))) | BU11: Ing No Recibida | BX11: =IF(BW11="","",IF(BW11="TBD","TBD",IF(BW11="N/A","N/A","W"&TEXT(WEEKNUM(BW11,21),"00")&" "&YEAR(BW11)))) | BZ11: =IF(BY11="","",IF(BY11="TBD","TBD",IF(BY11="N/A","N/A","W"&TEXT(WEEKNUM(BY11,21),"00")&" "&YEAR(BY11)))) | CA11: Ing No Recibida 4G | CB11: 0 | CI11: =IF(CH11="","",IF(CH11="TBD","TBD",IF(CH11="N/A","N/A","W"&TEXT(WEEKNUM(CH11,21),"00")&" "&YEAR(CH11)))) | CK11: =IF(CJ11="","",IF(CJ11="TBD","TBD",IF(CJ11="N/A","N/A","W"&TEXT(WEEKNUM(CJ11,21),"00")&" "&YEAR(CJ11)))) | CL11: =+IF(CJ11="",0,(CJ11-CH11)) -> 0 | CM11: As Built No Recibido | CP11: =IF(CO11="","",IF(CO11="TBD","TBD",IF(CO11="N/A","N/A","W"&TEXT(WEEKNUM(CO11,21),"00")&" "&YEAR(CO11)))) | CQ11: As Built No Recibido | CT11: =IF(CS11="","",IF(CS11="TBD","TBD",IF(CS11="N/A","N/A","W"&TEXT(WEEKNUM(CS11,21),"00")&" "&YEAR(CS11)))) | CU11: As Built No Recibido | CX11: =IF(CW11="","",IF(CW11="TBD","TBD",IF(CW11="N/A","N/A","W"&TEXT(WEEKNUM(CW11,21),"00")&" "&YEAR(CW11)))) | CY11: As Built No Recibido | DB11: =IF(DA11="","",IF(DA11="TBD","TBD",IF(DA11="N/A","N/A","W"&TEXT(WEEKNUM(DA11,21),"00")&" "&YEAR(DA11)))) | DD11: =IF(DC11="","",IF(DC11="TBD","TBD",IF(DC11="N/A","N/A","W"&TEXT(WEEKNUM(DC11,21),"00")&" "&YEAR(DC11)))) | DE11: As Built No Recibido | DG11: Gabinete Huawei | DK11: MMOO | DL11: Pendiente | DQ11: Huawei | EB11: En Etapa de TSS 4G | EI11: 0 | EJ11: =K11&AY11&CA11&DE11&DT11&DW11 -> No VigenteTSS No Recibido 4GIng No Recibida 4GAs Built No Recibido
A12: =IFERROR(IF(VLOOKUP(B12,SEARCH!A:A,1,0)=B12,"OK",""),"") | B12: 29_027 | C12: Cajon El Olivillo | D12: 9 | E12: -38.680417 | F12: -72.842889 | G12: La Araucanía | H12: Vilcún | I12: Pasaje los Coigues frente casa 288 | J12: Fase 1 - On Hold RF | K12: No Vigente | L12: No aplica | M12: 12 | O12: 0 | P12: BTS | Q12: 5-2-2025 Se informa por RF que sitios salen de plan 2024 (Correo Delfos) | R12: POSTE METALICO | S12: 12 | U12: 0 | V12: =IF(U12="","",IF(U12="TBD","TBD",IF(U12="N/A","N/A","W"&TEXT(WEEKNUM(U12,21),"00")&" "&YEAR(U12)))) -> W52 1900 | Y12: =IF(X12="","",IF(X12="TBD","TBD",IF(X12="N/A","N/A","W"&TEXT(WEEKNUM(X12,21),"00")&" "&YEAR(X12)))) | AB12: =+IF(Z12="",0,AA12-Z12) -> 0 | AC12: TSS No Recibido | AF12: =IF(AE12="","",IF(AE12="TBD","TBD",IF(AE12="N/A","N/A","W"&TEXT(WEEKNUM(AE12,21),"00")&" "&YEAR(AE12)))) | AG12: TSS No Recibido | AJ12: =IF(AI12="","",IF(AI12="TBD","TBD",IF(AI12="N/A","N/A","W"&TEXT(WEEKNUM(AI12,21),"00")&" "&YEAR(AI12)))) | AK12: TSS No Recibido | AN12: =IF(AM12="","",IF(AM12="TBD","TBD",IF(AM12="N/A","N/A","W"&TEXT(WEEKNUM(AM12,21),"00")&" "&YEAR(AM12)))) | AO12: TSS No Recibido | AR12: =IF(AQ12="","",IF(AQ12="TBD","TBD",IF(AQ12="N/A","N/A","W"&TEXT(WEEKNUM(AQ12,21),"00")&" "&YEAR(AQ12)))) | AX12: =IF(AW12="","",IF(AW12="TBD","TBD",IF(AW12="N/A","N/A","W"&TEXT(WEEKNUM(AW12,21),"00")&" "&YEAR(AW12)))) | AY12: TSS No Recibido 4G | AZ12: Pendiente FC | BA12: Contrato No Firmado | BE12: =IF(BD12="","",IF(BD12="TBD","TBD",IF(BD12="N/A","N/A","W"&TEXT(WEEKNUM(BD12,21),"00")&" "&YEAR(BD12)))) | BG12: =IF(BF12="","",IF(BF12="TBD","TBD",IF(BF12="N/A","N/A","W"&TEXT(WEEKNUM(BF12,21),"00")&" "&YEAR(BF12)))) | BH12: =+IF(BF12="",0,(BF12-BD12)) -> 0 | BI12: Ing No Recibida | BL12: =IF(BK12="","",IF(BK12="TBD","TBD",IF(BK12="N/A","N/A","W"&TEXT(WEEKNUM(BK12,21),"00")&" "&YEAR(BK12)))) | BM12: Ing No Recibida | BP12: =IF(BO12="","",IF(BO12="TBD","TBD",IF(BO12="N/A","N/A","W"&TEXT(WEEKNUM(BO12,21),"00")&" "&YEAR(BO12)))) | BQ12: Ing No Recibida | BT12: =IF(BS12="","",IF(BS12="TBD","TBD",IF(BS12="N/A","N/A","W"&TEXT(WEEKNUM(BS12,21),"00")&" "&YEAR(BS12)))) | BU12: Ing No Recibida | BX12: =IF(BW12="","",IF(BW12="TBD","TBD",IF(BW12="N/A","N/A","W"&TEXT(WEEKNUM(BW12,21),"00")&" "&YEAR(BW12)))) | BZ12: =IF(BY12="","",IF(BY12="TBD","TBD",IF(BY12="N/A","N/A","W"&TEXT(WEEKNUM(BY12,21),"00")&" "&YEAR(BY12)))) | CA12: Ing No Recibida 4G | CB12: 0 | CI12: =IF(CH12="","",IF(CH12="TBD","TBD",IF(CH12="N/A","N/A","W"&TEXT(WEEKNUM(CH12,21),"00")&" "&YEAR(CH12)))) | CK12: =IF(CJ12="","",IF(CJ12="TBD","TBD",IF(CJ12="N/A","N/A","W"&TEXT(WEEKNUM(CJ12,21),"00")&" "&YEAR(CJ12)))) | CL12: =+IF(CJ12="",0,(CJ12-CH12)) -> 0 | CM12: As Built No Recibido | CP12: =IF(CO12="","",IF(CO12="TBD","TBD",IF(CO12="N/A","N/A","W"&TEXT(WEEKNUM(CO12,21),"00")&" "&YEAR(CO12)))) | CQ12: As Built No Recibido | CT12: =IF(CS12="","",IF(CS12="TBD","TBD",IF(CS12="N/A","N/A","W"&TEXT(WEEKNUM(CS12,21),"00")&" "&YEAR(CS12)))) | CU12: As Built No Recibido | CX12: =IF(CW12="","",IF(CW12="TBD","TBD",IF(CW12="N/A","N/A","W"&TEXT(WEEKNUM(CW12,21),"00")&" "&YEAR(CW12)))) | CY12: As Built No Recibido | DB12: =IF(DA12="","",IF(DA12="TBD","TBD",IF(DA12="N/A","N/A","W"&TEXT(WEEKNUM(DA12,21),"00")&" "&YEAR(DA12)))) | DD12: =IF(DC12="","",IF(DC12="TBD","TBD",IF(DC12="N/A","N/A","W"&TEXT(WEEKNUM(DC12,21),"00")&" "&YEAR(DC12)))) | DE12: As Built No Recibido | DG12: Gabinete Huawei | DK12: MMOO | DL12: Pendiente | DQ12: Huawei | EB12: En Etapa de TSS 4G | EI12: 0 | EJ12: =K12&AY12&CA12&DE12&DT12&DW12 -> No VigenteTSS No Recibido 4GIng No Recibida 4GAs Built No Recibido
A13: =IFERROR(IF(VLOOKUP(B13,SEARCH!A:A,1,0)=B13,"OK",""),"") | B13: EE_049 | C13: Comp FEMSA SALUD SPA | D13: 13 | E13: -33.417326 | F13: -70.667056 | G13: Metropolitana de Santiago | H13: INDEPENDENCIA | I13: Nueva Andres Bello 1940 Independencia | J13: Indoor | K13: No Vigente | L13: No aplica | O13: 0 | P13: 0 | R13: Indoor - B2B | V13: =IF(U13="","",IF(U13="TBD","TBD",IF(U13="N/A","N/A","W"&TEXT(WEEKNUM(U13,21),"00")&" "&YEAR(U13)))) | Y13: =IF(X13="","",IF(X13="TBD","TBD",IF(X13="N/A","N/A","W"&TEXT(WEEKNUM(X13,21),"00")&" "&YEAR(X13)))) | AB13: =+IF(Z13="",0,AA13-Z13) -> 0 | AC13: TSS No Recibido | AF13: =IF(AE13="","",IF(AE13="TBD","TBD",IF(AE13="N/A","N/A","W"&TEXT(WEEKNUM(AE13,21),"00")&" "&YEAR(AE13)))) | AG13: TSS No Recibido | AJ13: =IF(AI13="","",IF(AI13="TBD","TBD",IF(AI13="N/A","N/A","W"&TEXT(WEEKNUM(AI13,21),"00")&" "&YEAR(AI13)))) | AK13: TSS No Recibido | AN13: =IF(AM13="","",IF(AM13="TBD","TBD",IF(AM13="N/A","N/A","W"&TEXT(WEEKNUM(AM13,21),"00")&" "&YEAR(AM13)))) | AO13: TSS No Recibido | AR13: =IF(AQ13="","",IF(AQ13="TBD","TBD",IF(AQ13="N/A","N/A","W"&TEXT(WEEKNUM(AQ13,21),"00")&" "&YEAR(AQ13)))) | AX13: =IF(AW13="","",IF(AW13="TBD","TBD",IF(AW13="N/A","N/A","W"&TEXT(WEEKNUM(AW13,21),"00")&" "&YEAR(AW13)))) | AY13: TSS No Recibido 4G | AZ13: Pendiente FC | BA13: Contrato No Firmado | BE13: =IF(BD13="","",IF(BD13="TBD","TBD",IF(BD13="N/A","N/A","W"&TEXT(WEEKNUM(BD13,21),"00")&" "&YEAR(BD13)))) | BG13: =IF(BF13="","",IF(BF13="TBD","TBD",IF(BF13="N/A","N/A","W"&TEXT(WEEKNUM(BF13,21),"00")&" "&YEAR(BF13)))) | BH13: =+IF(BF13="",0,(BF13-BD13)) -> 0 | BI13: Ing No Recibida | BL13: =IF(BK13="","",IF(BK13="TBD","TBD",IF(BK13="N/A","N/A","W"&TEXT(WEEKNUM(BK13,21),"00")&" "&YEAR(BK13)))) | BM13: Ing No Recibida | BP13: =IF(BO13="","",IF(BO13="TBD","TBD",IF(BO13="N/A","N/A","W"&TEXT(WEEKNUM(BO13,21),"00")&" "&YEAR(BO13)))) | BQ13: Ing No Recibida | BT13: =IF(BS13="","",IF(BS13="TBD","TBD",IF(BS13="N/A","N/A","W"&TEXT(WEEKNUM(BS13,21),"00")&" "&YEAR(BS13)))) | BU13: Ing No Recibida | BX13: =IF(BW13="","",IF(BW13="TBD","TBD",IF(BW13="N/A","N/A","W"&TEXT(WEEKNUM(BW13,21),"00")&" "&YEAR(BW13)))) | BZ13: =IF(BY13="","",IF(BY13="TBD","TBD",IF(BY13="N/A","N/A","W"&TEXT(WEEKNUM(BY13,21),"00")&" "&YEAR(BY13)))) | CA13: Ing No Recibida 4G | CB13: 0 | CI13: =IF(CH13="","",IF(CH13="TBD","TBD",IF(CH13="N/A","N/A","W"&TEXT(WEEKNUM(CH13,21),"00")&" "&YEAR(CH13)))) | CK13: =IF(CJ13="","",IF(CJ13="TBD","TBD",IF(CJ13="N/A","N/A","W"&TEXT(WEEKNUM(CJ13,21),"00")&" "&YEAR(CJ13)))) | CL13: =+IF(CJ13="",0,(CJ13-CH13)) -> 0 | CM13: As Built No Recibido | CP13: =IF(CO13="","",IF(CO13="TBD","TBD",IF(CO13="N/A","N/A","W"&TEXT(WEEKNUM(CO13,21),"00")&" "&YEAR(CO13)))) | CQ13: As Built No Recibido | CT13: =IF(CS13="","",IF(CS13="TBD","TBD",IF(CS13="N/A","N/A","W"&TEXT(WEEKNUM(CS13,21),"00")&" "&YEAR(CS13)))) | CU13: As Built No Recibido | CX13: =IF(CW13="","",IF(CW13="TBD","TBD",IF(CW13="N/A","N/A","W"&TEXT(WEEKNUM(CW13,21),"00")&" "&YEAR(CW13)))) | CY13: As Built No Recibido | DB13: =IF(DA13="","",IF(DA13="TBD","TBD",IF(DA13="N/A","N/A","W"&TEXT(WEEKNUM(DA13,21),"00")&" "&YEAR(DA13)))) | DD13: =IF(DC13="","",IF(DC13="TBD","TBD",IF(DC13="N/A","N/A","W"&TEXT(WEEKNUM(DC13,21),"00")&" "&YEAR(DC13)))) | DE13: As Built No Recibido | DG13: Por Definir | DK13: TBD | DL13: Pendiente | DQ13: ZTE | DY13: 0 | DZ13: 0 | EA13: 0 | EB13: En Etapa de TSS 4G | EI13: 0 | EJ13: =K13&AY13&CA13&DE13&DT13&DW13 -> No VigenteTSS No Recibido 4GIng No Recibida 4GAs Built No Recibido
A14: =IFERROR(IF(VLOOKUP(B14,SEARCH!A:A,1,0)=B14,"OK",""),"") | B14: 33i_968 | C14: Difarma Independencia | D14: 13 | E14: -33.417363 | F14: -70.667033 | G14: Metropolitana de Santiago | H14: INDEPENDENCIA | I14: Nueva Andres Bello 1940 | J14: Indoor | K14: No Vigente | O14: 0 | P14: 0 | R14: Indoor - B2B | U14: 0 | V14: =IF(U14="","",IF(U14="TBD","TBD",IF(U14="N/A","N/A","W"&TEXT(WEEKNUM(U14,21),"00")&" "&YEAR(U14)))) -> W52 1900 | Y14: =IF(X14="","",IF(X14="TBD","TBD",IF(X14="N/A","N/A","W"&TEXT(WEEKNUM(X14,21),"00")&" "&YEAR(X14)))) | AB14: =+IF(Z14="",0,AA14-Z14) -> 0 | AC14: TSS No Recibido | AF14: =IF(AE14="","",IF(AE14="TBD","TBD",IF(AE14="N/A","N/A","W"&TEXT(WEEKNUM(AE14,21),"00")&" "&YEAR(AE14)))) | AG14: TSS No Recibido | AJ14: =IF(AI14="","",IF(AI14="TBD","TBD",IF(AI14="N/A","N/A","W"&TEXT(WEEKNUM(AI14,21),"00")&" "&YEAR(AI14)))) | AK14: TSS No Recibido | AN14: =IF(AM14="","",IF(AM14="TBD","TBD",IF(AM14="N/A","N/A","W"&TEXT(WEEKNUM(AM14,21),"00")&" "&YEAR(AM14)))) | AO14: TSS No Recibido | AR14: =IF(AQ14="","",IF(AQ14="TBD","TBD",IF(AQ14="N/A","N/A","W"&TEXT(WEEKNUM(AQ14,21),"00")&" "&YEAR(AQ14)))) | AX14: =IF(AW14="","",IF(AW14="TBD","TBD",IF(AW14="N/A","N/A","W"&TEXT(WEEKNUM(AW14,21),"00")&" "&YEAR(AW14)))) | AY14: TSS No Recibido 4G | AZ14: Pendiente FC | BA14: Contrato No Firmado | BE14: =IF(BD14="","",IF(BD14="TBD","TBD",IF(BD14="N/A","N/A","W"&TEXT(WEEKNUM(BD14,21),"00")&" "&YEAR(BD14)))) | BG14: =IF(BF14="","",IF(BF14="TBD","TBD",IF(BF14="N/A","N/A","W"&TEXT(WEEKNUM(BF14,21),"00")&" "&YEAR(BF14)))) | BH14: =+IF(BF14="",0,(BF14-BD14)) -> 0 | BI14: Ing No Recibida | BL14: =IF(BK14="","",IF(BK14="TBD","TBD",IF(BK14="N/A","N/A","W"&TEXT(WEEKNUM(BK14,21),"00")&" "&YEAR(BK14)))) | BM14: Ing No Recibida | BP14: =IF(BO14="","",IF(BO14="TBD","TBD",IF(BO14="N/A","N/A","W"&TEXT(WEEKNUM(BO14,21),"00")&" "&YEAR(BO14)))) | BQ14: Ing No Recibida | BT14: =IF(BS14="","",IF(BS14="TBD","TBD",IF(BS14="N/A","N/A","W"&TEXT(WEEKNUM(BS14,21),"00")&" "&YEAR(BS14)))) | BU14: Ing No Recibida | BX14: =IF(BW14="","",IF(BW14="TBD","TBD",IF(BW14="N/A","N/A","W"&TEXT(WEEKNUM(BW14,21),"00")&" "&YEAR(BW14)))) | BZ14: =IF(BY14="","",IF(BY14="TBD","TBD",IF(BY14="N/A","N/A","W"&TEXT(WEEKNUM(BY14,21),"00")&" "&YEAR(BY14)))) | CA14: Ing No Recibida 4G | CB14: 0 | CI14: =IF(CH14="","",IF(CH14="TBD","TBD",IF(CH14="N/A","N/A","W"&TEXT(WEEKNUM(CH14,21),"00")&" "&YEAR(CH14)))) | CK14: =IF(CJ14="","",IF(CJ14="TBD","TBD",IF(CJ14="N/A","N/A","W"&TEXT(WEEKNUM(CJ14,21),"00")&" "&YEAR(CJ14)))) | CL14: =+IF(CJ14="",0,(CJ14-CH14)) -> 0 | CM14: As Built No Recibido | CP14: =IF(CO14="","",IF(CO14="TBD","TBD",IF(CO14="N/A","N/A","W"&TEXT(WEEKNUM(CO14,21),"00")&" "&YEAR(CO14)))) | CQ14: As Built No Recibido | CT14: =IF(CS14="","",IF(CS14="TBD","TBD",IF(CS14="N/A","N/A","W"&TEXT(WEEKNUM(CS14,21),"00")&" "&YEAR(CS14)))) | CU14: As Built No Recibido | CX14: =IF(CW14="","",IF(CW14="TBD","TBD",IF(CW14="N/A","N/A","W"&TEXT(WEEKNUM(CW14,21),"00")&" "&YEAR(CW14)))) | CY14: As Built No Recibido | DB14: =IF(DA14="","",IF(DA14="TBD","TBD",IF(DA14="N/A","N/A","W"&TEXT(WEEKNUM(DA14,21),"00")&" "&YEAR(DA14)))) | DD14: =IF(DC14="","",IF(DC14="TBD","TBD",IF(DC14="N/A","N/A","W"&TEXT(WEEKNUM(DC14,21),"00")&" "&YEAR(DC14)))) | DE14: As Built No Recibido | DG14: Por Definir | DK14: TBD | DL14: Pendiente | EB14: En Etapa de TSS 4G | EI14: 0 | EJ14: =K14&AY14&CA14&DE14&DT14&DW14 -> No VigenteTSS No Recibido 4GIng No Recibida 4GAs Built No Recibido
A15: =IFERROR(IF(VLOOKUP(B15,SEARCH!A:A,1,0)=B15,"OK",""),"") | B15: 53_394 | C15: Aeropuerto Santiago - Pista de Aterrizaje | D15: 13 | E15: -33.3822 | F15: -70.798 | G15: Metropolitana de Santiago | H15: SANTIAGO | I15: 0 | J15: Indoor | K15: No Vigente | O15: 0 | P15: 0 | Q15: Correo Delfos 8-4-2025: Informa que sitios salen de plan 290. Se pide formalizar con Inmobiliaria esta gestión | R15: Indoor - B2C | U15: 0 | V15: =IF(U15="","",IF(U15="TBD","TBD",IF(U15="N/A","N/A","W"&TEXT(WEEKNUM(U15,21),"00")&" "&YEAR(U15)))) -> W52 1900 | Y15: =IF(X15="","",IF(X15="TBD","TBD",IF(X15="N/A","N/A","W"&TEXT(WEEKNUM(X15,21),"00")&" "&YEAR(X15)))) | AB15: =+IF(Z15="",0,AA15-Z15) -> 0 | AC15: TSS No Recibido | AF15: =IF(AE15="","",IF(AE15="TBD","TBD",IF(AE15="N/A","N/A","W"&TEXT(WEEKNUM(AE15,21),"00")&" "&YEAR(AE15)))) | AG15: TSS No Recibido | AJ15: =IF(AI15="","",IF(AI15="TBD","TBD",IF(AI15="N/A","N/A","W"&TEXT(WEEKNUM(AI15,21),"00")&" "&YEAR(AI15)))) | AK15: TSS No Recibido | AN15: =IF(AM15="","",IF(AM15="TBD","TBD",IF(AM15="N/A","N/A","W"&TEXT(WEEKNUM(AM15,21),"00")&" "&YEAR(AM15)))) | AO15: TSS No Recibido | AR15: =IF(AQ15="","",IF(AQ15="TBD","TBD",IF(AQ15="N/A","N/A","W"&TEXT(WEEKNUM(AQ15,21),"00")&" "&YEAR(AQ15)))) | AX15: =IF(AW15="","",IF(AW15="TBD","TBD",IF(AW15="N/A","N/A","W"&TEXT(WEEKNUM(AW15,21),"00")&" "&YEAR(AW15)))) | AY15: TSS No Recibido 4G | AZ15: Pendiente FC | BA15: Contrato No Firmado | BE15: =IF(BD15="","",IF(BD15="TBD","TBD",IF(BD15="N/A","N/A","W"&TEXT(WEEKNUM(BD15,21),"00")&" "&YEAR(BD15)))) | BG15: =IF(BF15="","",IF(BF15="TBD","TBD",IF(BF15="N/A","N/A","W"&TEXT(WEEKNUM(BF15,21),"00")&" "&YEAR(BF15)))) | BH15: =+IF(BF15="",0,(BF15-BD15)) -> 0 | BI15: Ing No Recibida | BL15: =IF(BK15="","",IF(BK15="TBD","TBD",IF(BK15="N/A","N/A","W"&TEXT(WEEKNUM(BK15,21),"00")&" "&YEAR(BK15)))) | BM15: Ing No Recibida | BP15: =IF(BO15="","",IF(BO15="TBD","TBD",IF(BO15="N/A","N/A","W"&TEXT(WEEKNUM(BO15,21),"00")&" "&YEAR(BO15)))) | BQ15: Ing No Recibida | BT15: =IF(BS15="","",IF(BS15="TBD","TBD",IF(BS15="N/A","N/A","W"&TEXT(WEEKNUM(BS15,21),"00")&" "&YEAR(BS15)))) | BU15: Ing No Recibida | BX15: =IF(BW15="","",IF(BW15="TBD","TBD",IF(BW15="N/A","N/A","W"&TEXT(WEEKNUM(BW15,21),"00")&" "&YEAR(BW15)))) | BZ15: =IF(BY15="","",IF(BY15="TBD","TBD",IF(BY15="N/A","N/A","W"&TEXT(WEEKNUM(BY15,21),"00")&" "&YEAR(BY15)))) | CA15: Ing No Recibida 4G | CB15: 0 | CI15: =IF(CH15="","",IF(CH15="TBD","TBD",IF(CH15="N/A","N/A","W"&TEXT(WEEKNUM(CH15,21),"00")&" "&YEAR(CH15)))) | CK15: =IF(CJ15="","",IF(CJ15="TBD","TBD",IF(CJ15="N/A","N/A","W"&TEXT(WEEKNUM(CJ15,21),"00")&" "&YEAR(CJ15)))) | CL15: =+IF(CJ15="",0,(CJ15-CH15)) -> 0 | CM15: As Built No Recibido | CP15: =IF(CO15="","",IF(CO15="TBD","TBD",IF(CO15="N/A","N/A","W"&TEXT(WEEKNUM(CO15,21),"00")&" "&YEAR(CO15)))) | CQ15: As Built No Recibido | CT15: =IF(CS15="","",IF(CS15="TBD","TBD",IF(CS15="N/A","N/A","W"&TEXT(WEEKNUM(CS15,21),"00")&" "&YEAR(CS15)))) | CU15: As Built No Recibido | CX15: =IF(CW15="","",IF(CW15="TBD","TBD",IF(CW15="N/A","N/A","W"&TEXT(WEEKNUM(CW15,21),"00")&" "&YEAR(CW15)))) | CY15: As Built No Recibido | DB15: =IF(DA15="","",IF(DA15="TBD","TBD",IF(DA15="N/A","N/A","W"&TEXT(WEEKNUM(DA15,21),"00")&" "&YEAR(DA15)))) | DD15: =IF(DC15="","",IF(DC15="TBD","TBD",IF(DC15="N/A","N/A","W"&TEXT(WEEKNUM(DC15,21),"00")&" "&YEAR(DC15)))) | DE15: As Built No Recibido | DG15: Por Definir | DK15: TBD | DL15: Pendiente | EB15: En Etapa de TSS 4G | EI15: 0 | EJ15: =K15&AY15&CA15&DE15&DT15&DW15 -> No VigenteTSS No Recibido 4GIng No Recibida 4GAs Built No Recibido
A16: =IFERROR(IF(VLOOKUP(B16,SEARCH!A:A,1,0)=B16,"OK",""),"") | B16: 23_790 | C16: Barrio Industrial de Quilicura | D16: 13 | E16: -33.326931 | F16: -70.717026 | G16: Metropolitana de Santiago | H16: Quilicura | I16: Eduardo Frei Montalva 9951 | J16: Fase 2 | K16: Vigente | L16: No aplica | M16: Sitio Recibido | O16: ANTYL | P16: 0 | R16: MONOPOSTE | S16: 14 | T16: ANT230_13 | U16: 45527 | V16: =IF(U16="","",IF(U16="TBD","TBD",IF(U16="N/A","N/A","W"&TEXT(WEEKNUM(U16,21),"00")&" "&YEAR(U16)))) -> W34 2024 | W16: 45531 | Y16: =IF(X16="","",IF(X16="TBD","TBD",IF(X16="N/A","N/A","W"&TEXT(WEEKNUM(X16,21),"00")&" "&YEAR(X16)))) | Z16: 45531 | AA16: 45534 | AB16: =+IF(Z16="",0,AA16-Z16) -> 3 | AC16: TSS Aprobado | AE16: 45534 | AF16: =IF(AE16="","",IF(AE16="TBD","TBD",IF(AE16="N/A","N/A","W"&TEXT(WEEKNUM(AE16,21),"00")&" "&YEAR(AE16)))) -> W35 2024 | AG16: TSS Aprobado | AH16: Rev.2 09-09: Aprobado 1. Area en piso: 3x2m 2. Soporte RF: 3 soportes H. | AI16: 45544 | AJ16: =IF(AI16="","",IF(AI16="TBD","TBD",IF(AI16="N/A","N/A","W"&TEXT(WEEKNUM(AI16,21),"00")&" "&YEAR(AI16)))) -> W37 2024 | AK16: TSS Aprobado | AL16: Distribución de equipos se verificará en ingenieria. | AM16: 45544 | AN16: =IF(AM16="","",IF(AM16="TBD","TBD",IF(AM16="N/A","N/A","W"&TEXT(WEEKNUM(AM16,21),"00")&" "&YEAR(AM16)))) -> W37 2024 | AO16: TSS Aprobado | AQ16: 45545 | AR16: =IF(AQ16="","",IF(AQ16="TBD","TBD",IF(AQ16="N/A","N/A","W"&TEXT(WEEKNUM(AQ16,21),"00")&" "&YEAR(AQ16)))) -> W37 2024 | AW16: 45545 | AX16: =IF(AW16="","",IF(AW16="TBD","TBD",IF(AW16="N/A","N/A","W"&TEXT(WEEKNUM(AW16,21),"00")&" "&YEAR(AW16)))) -> W37 2024 | AY16: TSS Aprobado 4G | AZ16: FC Enviado a OOII | BA16: Contrato Firmado | BB16: 45588 | BC16: 45607 | BD16: 45608 | BE16: =IF(BD16="","",IF(BD16="TBD","TBD",IF(BD16="N/A","N/A","W"&TEXT(WEEKNUM(BD16,21),"00")&" "&YEAR(BD16)))) -> W46 2024 | BF16: 45610 | BG16: =IF(BF16="","",IF(BF16="TBD","TBD",IF(BF16="N/A","N/A","W"&TEXT(WEEKNUM(BF16,21),"00")&" "&YEAR(BF16)))) -> W46 2024 | BH16: =+IF(BF16="",0,(BF16-BD16)) -> 2 | BI16: Ing Aprobada | BJ16: 21-11: Aprobado Se levantan las observaciones indicadas en revisiones anteriores. 13-11: Observado 1. Si se va a destinar los soportes de RF para instalar la MMOO, 1 de estos debe ser de 3", ya que el diametro minimo solicitado por el equipo de ing. MMOO es de 3" y maximo 4". | BK16: 45617 | BL16: =IF(BK16="","",IF(BK16="TBD","TBD",IF(BK16="N/A","N/A","W"&TEXT(WEEKNUM(BK16,21),"00")&" "&YEAR(BK16)))) -> W47 2024 | BM16: Ing Aprobada | BN16: 08/11: Observaciones corregidas a nivel de RF, solo aclarar porque no se considerar 2 soporte x sector | BO16: 45604 | BP16: =IF(BO16="","",IF(BO16="TBD","TBD",IF(BO16="N/A","N/A","W"&TEXT(WEEKNUM(BO16,21),"00")&" "&YEAR(BO16)))) -> W45 2024 | BQ16: Ing Aprobada | BR16: 08-11-2024: Observado V3 - Soporte MMOO: Proyectado: NO-OK - Dimensiones soporte MMOO: L=1 : D=4": NO-OK | BS16: 45629 | BT16: =IF(BS16="","",IF(BS16="TBD","TBD",IF(BS16="N/A","N/A","W"&TEXT(WEEKNUM(BS16,21),"00")&" "&YEAR(BS16)))) -> W49 2024 | BU16: Ing Aprobada | BV16: REV2 24-10-2024 Área proyectada 3x2 mts Empalme aéreo trifásico independiente proyectado desde poste referencia # 728180 Acometida eléctrica aérea trifásica proyectada ( L=5 mts ) Línea eléctrica subterránea proyectada (L=40 mts) (6AWG) TDAyF + Medidor Trifásico Proyectado Tierra proyectada (Conexión a malla existente) | BW16: 45589 | BX16: =IF(BW16="","",IF(BW16="TBD","TBD",IF(BW16="N/A","N/A","W"&TEXT(WEEKNUM(BW16,21),"00")&" "&YEAR(BW16)))) -> W43 2024 | BY16: 45629 | BZ16: =IF(BY16="","",IF(BY16="TBD","TBD",IF(BY16="N/A","N/A","W"&TEXT(WEEKNUM(BY16,21),"00")&" "&YEAR(BY16)))) -> W49 2024 | CA16: Ing Aprobada 4G | CB16: Finalizadas | CC16: Finalizadas | CD16: Sin Energía Provisoria | CE16: Si | CF16: 45714 | CG16: 45744 | CH16: 45727 | CI16: =IF(CH16="","",IF(CH16="TBD","TBD",IF(CH16="N/A","N/A","W"&TEXT(WEEKNUM(CH16,21),"00")&" "&YEAR(CH16)))) -> W11 2025 | CJ16: 45730 | CK16: =IF(CJ16="","",IF(CJ16="TBD","TBD",IF(CJ16="N/A","N/A","W"&TEXT(WEEKNUM(CJ16,21),"00")&" "&YEAR(CJ16)))) -> W11 2025 | CL16: =+IF(CJ16="",0,(CJ16-CH16)) -> 3 | CM16: As Built Aprobado | CN16: 0 | CO16: 45747 | CP16: =IF(CO16="","",IF(CO16="TBD","TBD",IF(CO16="N/A","N/A","W"&TEXT(WEEKNUM(CO16,21),"00")&" "&YEAR(CO16)))) -> W14 2025 | CQ16: As Built Aprobado | CS16: 45756 | CT16: =IF(CS16="","",IF(CS16="TBD","TBD",IF(CS16="N/A","N/A","W"&TEXT(WEEKNUM(CS16,21),"00")&" "&YEAR(CS16)))) -> W15 2025 | CU16: As Built Aprobado | CW16: 45747 | CX16: =IF(CW16="","",IF(CW16="TBD","TBD",IF(CW16="N/A","N/A","W"&TEXT(WEEKNUM(CW16,21),"00")&" "&YEAR(CW16)))) -> W14 2025 | CY16: As Built Aprobado | DA16: 45747 | DB16: =IF(DA16="","",IF(DA16="TBD","TBD",IF(DA16="N/A","N/A","W"&TEXT(WEEKNUM(DA16,21),"00")&" "&YEAR(DA16)))) -> W14 2025 | DC16: 45756 | DD16: =IF(DC16="","",IF(DC16="TBD","TBD",IF(DC16="N/A","N/A","W"&TEXT(WEEKNUM(DC16,21),"00")&" "&YEAR(DC16)))) -> W15 2025 | DE16: As Built Aprobado 4G | DF16: 45769 | DG16: Gabinete Huawei | DK16: FO | DL16: ODF Instalado | DN16: 45833 | DO16: 45833 | DQ16: ZTE | DV16: 45848 | DW16: On Air | EB16: On Air 4G | ED16: Plan 2025 | EI16: 0 | EJ16: =K16&AY16&CA16&DE16&DT16&DW16 -> VigenteTSS Aprobado 4GIng Aprobada 4GAs Built Aprobado 4GOn Air
A17: =IFERROR(IF(VLOOKUP(B17,SEARCH!A:A,1,0)=B17,"OK",""),"") | B17: 25_214 | C17: Isla Negra | D17: 5 | E17: -33.427078 | F17: -71.688067 | G17: Valparaíso | I17: Pendiente TSS | J17: No Vigente | K17: No Vigente | L17: No aplica | O17: ANTYL | P17: BTS | R17: POSTE METALICO | S17: #N/A | T17: PENDIENTE | U17: 45161 | V17: =IF(U17="","",IF(U17="TBD","TBD",IF(U17="N/A","N/A","W"&TEXT(WEEKNUM(U17,21),"00")&" "&YEAR(U17)))) -> W34 2023 | Y17: =IF(X17="","",IF(X17="TBD","TBD",IF(X17="N/A","N/A","W"&TEXT(WEEKNUM(X17,21),"00")&" "&YEAR(X17)))) | AB17: =+IF(Z17="",0,AA17-Z17) -> 0 | AC17: TSS No Recibido | AD17: 0 | AF17: =IF(AE17="","",IF(AE17="TBD","TBD",IF(AE17="N/A","N/A","W"&TEXT(WEEKNUM(AE17,21),"00")&" "&YEAR(AE17)))) | AG17: TSS No Recibido | AJ17: =IF(AI17="","",IF(AI17="TBD","TBD",IF(AI17="N/A","N/A","W"&TEXT(WEEKNUM(AI17,21),"00")&" "&YEAR(AI17)))) | AK17: TSS No Recibido | AN17: =IF(AM17="","",IF(AM17="TBD","TBD",IF(AM17="N/A","N/A","W"&TEXT(WEEKNUM(AM17,21),"00")&" "&YEAR(AM17)))) | AO17: TSS No Recibido | AR17: =IF(AQ17="","",IF(AQ17="TBD","TBD",IF(AQ17="N/A","N/A","W"&TEXT(WEEKNUM(AQ17,21),"00")&" "&YEAR(AQ17)))) | AX17: =IF(AW17="","",IF(AW17="TBD","TBD",IF(AW17="N/A","N/A","W"&TEXT(WEEKNUM(AW17,21),"00")&" "&YEAR(AW17)))) | AY17: TSS No Recibido 4G | AZ17: FC Enviado a OOII | BA17: Contrato No Firmado | BE17: =IF(BD17="","",IF(BD17="TBD","TBD",IF(BD17="N/A","N/A","W"&TEXT(WEEKNUM(BD17,21),"00")&" "&YEAR(BD17)))) | BG17: =IF(BF17="","",IF(BF17="TBD","TBD",IF(BF17="N/A","N/A","W"&TEXT(WEEKNUM(BF17,21),"00")&" "&YEAR(BF17)))) | BH17: =+IF(BF17="",0,(BF17-BD17)) -> 0 | BI17: Ing No Recibida | BL17: =IF(BK17="","",IF(BK17="TBD","TBD",IF(BK17="N/A","N/A","W"&TEXT(WEEKNUM(BK17,21),"00")&" "&YEAR(BK17)))) | BM17: Ing No Recibida | BP17: =IF(BO17="","",IF(BO17="TBD","TBD",IF(BO17="N/A","N/A","W"&TEXT(WEEKNUM(BO17,21),"00")&" "&YEAR(BO17)))) | BQ17: Ing No Recibida | BT17: =IF(BS17="","",IF(BS17="TBD","TBD",IF(BS17="N/A","N/A","W"&TEXT(WEEKNUM(BS17,21),"00")&" "&YEAR(BS17)))) | BU17: Ing No Recibida | BX17: =IF(BW17="","",IF(BW17="TBD","TBD",IF(BW17="N/A","N/A","W"&TEXT(WEEKNUM(BW17,21),"00")&" "&YEAR(BW17)))) | BZ17: =IF(BY17="","",IF(BY17="TBD","TBD",IF(BY17="N/A","N/A","W"&TEXT(WEEKNUM(BY17,21),"00")&" "&YEAR(BY17)))) | CA17: Ing No Recibida 4G | CB17: No Iniciadas | CC17: No iniciadas | CI17: =IF(CH17="","",IF(CH17="TBD","TBD",IF(CH17="N/A","N/A","W"&TEXT(WEEKNUM(CH17,21),"00")&" "&YEAR(CH17)))) | CK17: =IF(CJ17="","",IF(CJ17="TBD","TBD",IF(CJ17="N/A","N/A","W"&TEXT(WEEKNUM(CJ17,21),"00")&" "&YEAR(CJ17)))) | CL17: =+IF(CJ17="",0,(CJ17-CH17)) -> 0 | CM17: As Built No Recibido | CP17: =IF(CO17="","",IF(CO17="TBD","TBD",IF(CO17="N/A","N/A","W"&TEXT(WEEKNUM(CO17,21),"00")&" "&YEAR(CO17)))) | CQ17: As Built No Recibido | CT17: =IF(CS17="","",IF(CS17="TBD","TBD",IF(CS17="N/A","N/A","W"&TEXT(WEEKNUM(CS17,21),"00")&" "&YEAR(CS17)))) | CU17: As Built No Recibido | CX17: =IF(CW17="","",IF(CW17="TBD","TBD",IF(CW17="N/A","N/A","W"&TEXT(WEEKNUM(CW17,21),"00")&" "&YEAR(CW17)))) | CY17: As Built No Recibido | DB17: =IF(DA17="","",IF(DA17="TBD","TBD",IF(DA17="N/A","N/A","W"&TEXT(WEEKNUM(DA17,21),"00")&" "&YEAR(DA17)))) | DD17: =IF(DC17="","",IF(DC17="TBD","TBD",IF(DC17="N/A","N/A","W"&TEXT(WEEKNUM(DC17,21),"00")&" "&YEAR(DC17)))) | DE17: As Built No Recibido | DG17: Gabinete Huawei | DK17: FO | DL17: Pendiente | DQ17: ZTE | EB17: En Etapa de TSS 4G | EI17: 0 | EJ17: =K17&AY17&CA17&DE17&DT17&DW17 -> No VigenteTSS No Recibido 4GIng No Recibida 4GAs Built No Recibido
